#####################################################################################
#
#  Copyright (c) Microsoft Corporation. All rights reserved.
#
# This source code is subject to terms and conditions of the Apache License, Version 2.0. A
# copy of the license can be found in the License.html file at the root of this distribution. If
# you cannot locate the  Apache License, Version 2.0, please send an email to
# ironpy@microsoft.com. By using this source code in any fashion, you are agreeing to be bound
# by the terms of the Apache License, Version 2.0.
#
# You must not remove this notice, or any other, from this software.
#
#
#####################################################################################

# !!! DO NOT MOVE OR CHANGE THE FOLLOWING LINES
def _raise_exception():
    raise Exception()

_retb = (18, 0, 'test_traceback.py', '_raise_exception')

from iptest.assert_util import *
from iptest.file_util import *
if not is_cli: import os
def _raise_exception_with_finally():
    try:
        raise Exception()
    finally:
        pass

_rewftb= (27, 0, 'test_traceback.py', '_raise_exception_with_finally')

def assert_traceback(expected):
    import sys
    tb = sys.exc_info()[2]
    
    if expected is None:
        AreEqual(None, expected)
    else:
        tb_list = []
        while tb is not None :
            f = tb.tb_frame
            co = f.f_code
            filename = co.co_filename.lower()
            name = co.co_name
            tb_list.append((tb.tb_lineno, tb.tb_lasti, filename, name))
            tb = tb.tb_next
        
        #print tb_list
        
        AreEqual(len(tb_list), len(expected))
        
        for x in range(len(expected)):
            AreEqual(tb_list[x][0], expected[x][0])
            AreEqual(tb_list[x][2:], expected[x][2:])
            

def test_no_traceback():
    #assert_traceback(None)
    try:
        _raise_exception()
    except:
        pass
    assert_traceback(None)

FILE="test_traceback.py"

LINE100 = 70

def test_catch_others_exception():
    try:
        _raise_exception()
    except:
        assert_traceback([(LINE100 + 2, 0, FILE, 'test_catch_others_exception'), _retb])

LINE110 = 78

def test_catch_its_own_exception():
    try:
        raise Exception()
    except:
        assert_traceback([(LINE110 + 2, 0, FILE, 'test_catch_its_own_exception')])

LINE120 = 86

def test_catch_others_exception_with_finally():
    try:
        _raise_exception_with_finally()
    except:
        assert_traceback([(LINE120 + 2, 0, FILE, 'test_catch_others_exception_with_finally'), _rewftb])

LINE130 = 94

def test_nested_caught_outside():
    try:
        x = 2
        try:
            _raise_exception()
        except NameError:
            Assert(False, "unhittable")
        y = 2
    except:
        assert_traceback([(LINE130 + 4, 0, FILE, 'test_nested_caught_outside'), _retb])

LINE140 = 108

def test_nested_caught_inside():
    try:
        x = 2
        try:
            _raise_exception()
        except:
            assert_traceback([(LINE140 + 4, 0, FILE, 'test_nested_caught_inside'), _retb])
        y = 2
    except:
        assert_traceback(None)

LINE150 = 120

def test_throw_in_except():
    try:
        _raise_exception()
    except:
        assert_traceback([(LINE150+2, 0, FILE, 'test_throw_in_except'), _retb])
        try:
            assert_traceback([(LINE150+2, 0, FILE, 'test_throw_in_except'), _retb])
            _raise_exception()
        except:
            assert_traceback([(LINE150+7, 0, FILE, 'test_throw_in_except'), _retb])
    assert_traceback([(LINE150+7, 0, FILE, 'test_throw_in_except'), _retb])

LINE160 = 134

class C1:
    def M(self):
        try:
            _raise_exception()
        except:
            assert_traceback([(LINE160 + 3, 0, FILE, 'M'), _retb])

def test_throw_in_method():
    c = C1()
    c.M()

LINE170 = 147

def test_throw_when_defining_class():
    class C2(object):
        try:
            _raise_exception()
        except:
            assert_traceback([(LINE170 + 3, 0, FILE, 'C2'), _retb])

def throw_when_defining_class_directly():
    class C3(C1):
        _raise_exception()

LINE180 = 160

def test_throw_when_defining_class_directly():
    try:
        throw_when_defining_class_directly()
    except:
        assert_traceback([(LINE180 + 2, 0, FILE, 'test_throw_when_defining_class_directly'),
        (LINE180 - 5, 0, FILE, 'throw_when_defining_class_directly'),
        (LINE180 - 4, 0, FILE, 'C3'), _retb])
LINE200 = 169

def test_compiled_code():
    try:
        codeobj = compile('\nraise Exception()', '<mycode>', 'exec')
        exec(codeobj, {})
    except:
        assert_traceback([(LINE200+3, 0, FILE, 'test_compiled_code'), (2, 0, '<mycode>', '<module>')])

def generator_throw_before_yield():
    _raise_exception()
    yield 1
    
LINE210 = 181

def test_throw_before_yield():
    try:
        for x in generator_throw_before_yield():
            pass
    except:
        assert_traceback([(LINE210+3, 0, FILE, 'test_throw_before_yield'), (LINE210-4, 2, 'test_traceback.py', 'generator_throw_before_yield'), _retb])

def generator_throw_after_yield():
    yield 1
    _raise_exception()

LINE220 = 194

def test_throw_while_yield():
    try:
        for x in generator_throw_while_yield():
            pass
    except:
        assert_traceback([(LINE220+3, 0, FILE, 'test_throw_while_yield')])

def generator_yield_inside_try():
    try:
        yield 1
        yield 2
        _raise_exception()
    except NameError:
        pass

LINE230 = 211

def test_yield_inside_try():
    try:
        for x in generator_yield_inside_try():
            pass
    except:
        assert_traceback([(LINE230+3, 0, FILE, 'test_yield_inside_try'), (LINE230-5, 2, 'test_traceback.py', 'generator_yield_inside_try'), _retb])

LINE240 = 221

def test_throw_and_throw():
    try:
        _raise_exception()
    except:
        assert_traceback([(LINE240 + 2, 0, FILE, 'test_throw_and_throw'), _retb])
    try:
        _raise_exception()
    except:
        assert_traceback([(LINE240 + 6, 0, FILE, 'test_throw_and_throw'), _retb])
LINE250 = 233

def test_throw_in_another_file():
    if is_cli: _f_file = path_combine(get_full_dir_name(testpath.public_testdir), 'foo.py')
    else: _f_file = os.getcwd() + '\\foo.py'
    write_to_file(_f_file, '''
def another_raise():
    raise Exception()
''');
    try:
        import foo
        foo.another_raise()
    except:
        assert_traceback([(LINE250 + 8, 0, FILE, 'test_throw_in_another_file'), (3, 0, _f_file.lower(), 'another_raise')])
    finally:
        os.remove(_f_file)

class MyException(Exception): pass

Line260 = 250
def catch_MyException():
    try:
        _raise_exception()
    except MyException:
        assert_traceback([])  # UNREACABLE. THIS TRICK SIMPLIFIES THE CHECK

def test_catch_MyException():
    try:
        catch_MyException()
    except:
        assert_traceback([(Line260+8, 0, FILE, 'test_catch_MyException'), (Line260+2, 0, FILE, 'catch_MyException'), _retb])

Line263 = 263

def test_cp11923_first():
    try:
        _t_test = path_combine(testpath.public_testdir, "cp11923.py")
        write_to_file(_t_test, """def f():
    x = 'something bad'
    raise Exception(x)""")
        
        import cp11923
        for i in xrange(3):
            try:
                cp11923.f()
            except:
                assert_traceback([(Line263 + 11, 69, 'test_traceback.py', 'test_cp11923_first'), (3, 22, get_full_dir_name(_t_test).lower(), 'f')])
            reload(cp11923)
        
    finally:
        import os
        os.unlink(_t_test)

###############################################################################
##TESTS BEYOND THIS POINT SHOULD NOT DEPEND ON LINE NUMBERS IN THIS FILE#######
###############################################################################

def test_cp11923_second():
    import os
    import sys
    old_path = [x for x in sys.path]
    sys.path.append(os.getcwd())
        
    try:
        #Test setup
        _t_test = os.path.join(testpath.public_testdir, "cp11116_main.py")
        write_to_file(_t_test, """import cp11116_a
try:
    cp11116_a.a()
except:
    pass

cp11116_a.a()
""")
       
        _t_test_a = os.path.join(testpath.public_testdir, "cp11116_a.py")
        write_to_file(_t_test_a, """def a():
    raise None
""") 
        
        #Actual test
        t_out, t_in, t_err = os.popen3(sys.executable + " " + os.path.join(os.getcwd(), "cp11116_main.py"))
        lines = t_err.readlines()
        t_err.close()
        t_out.close()
        t_in.close()
                
        #Verification
        Assert("cp11116_main.py\", line 7, in" in lines[1], lines[1])
        line_num = 3
        if is_cli:
            line_num -= 1
        Assert(lines[line_num].rstrip().endswith("cp11116_a.py\", line 2, in a"), lines[line_num])
        
    finally:
        sys.path = old_path
        os.unlink(_t_test)
        os.unlink(_t_test_a)

Line331 = 332
def test_reraise():
    def g():
        f()
    
    def f():
        try:
            raise Exception
        except:
            raise

    try:
        g()
    except:
        assert_traceback([(Line331+9, 0, 'test_traceback.py', 'test_reraise'), (Line331, 0, 'test_traceback.py', 'g'), (Line331+4, 0, 'test_traceback.py', 'f')])


def test_reraise_finally():
    def g():
        f()
    
    def f():
        try:
            raise Exception
        finally:
            raise

    try:
        g()
    except:
        assert_traceback([(Line331+25, 30, 'test_traceback.py', 'test_reraise_finally'), (Line331+16, 3, 'test_traceback.py', 'g'), (Line331+22,13, 'test_traceback.py', 'f')])

Line361 = 361
def test_xafter_finally_raise():
    def g():
        raise Exception
    
    def nop(): pass
    
    def f():
        try:
            nop()
        finally:
            nop()
            
        try:
            g()
        except Exception, e:
            assert_traceback([(Line361+14, 30, 'test_traceback.py', 'f'), (Line361+3, 3, 'test_traceback.py', 'g')])

    f()

Line381 = 381
def test_uncaught_exception_thru_try():
    def baz():
        raise StopIteration
    
    def f():
        try:
            baz()
        except TypeError:
            pass
    try:
        f()
    except:
        assert_traceback([(Line381+11, 30, 'test_traceback.py', 'test_uncaught_exception_thru_try'), (Line381+7, 3, 'test_traceback.py', 'f'), (Line381+3, 3, 'test_traceback.py', 'baz')])


Line397=397
def test_with_traceback():
    from thread import allocate_lock
    def f():
        g()
    
    def g():
        h()
    
    def h():
        raise Exception('hello!!')
        
    try:
        with allocate_lock():
            f()
    except:
        assert_traceback([(Line397+14, 30, 'test_traceback.py', 'test_with_traceback'), 
                          (Line397+4, 3, 'test_traceback.py', 'f'), 
                          (Line397+7, 3, 'test_traceback.py', 'g'),
                          (Line397+10, 3, 'test_traceback.py', 'h')])
        

Line419=419
def test_xraise_again():
    def f():
        g()
    
    def g():
        h()
    
    def h():
        raise Exception('hello!!')
        
    try:
        try:
            f()
        except Exception, e:
            raise e
    except:
        assert_traceback([(Line419+15, 30, 'test_traceback.py', 'test_xraise_again'), ])

Line438=438
def test_with_traceback_enter_throws():
    class ctx_mgr(object):
        def __enter__(*args):
            raise Exception('hello')
        def __exit__(*args):
            pass
    
    def h():
        raise Exception('hello!!')
        
        
    try:
        with ctx_mgr():
            h()
    except:
        assert_traceback([(Line438+13, 30, 'test_traceback.py', 'test_with_traceback_enter_throws'), 
                          (Line438+4, 3, 'test_traceback.py', '__enter__')])
                          
Line457=457
def test_with_traceback_exit_throws():
    class ctx_mgr(object):
        def __enter__(*args):
            pass
        def __exit__(*args):
            raise Exception('hello')
    
    def h():
        raise Exception('hello!!')
        
    try:
        with ctx_mgr():
            h()
    except:
        assert_traceback([(Line457+13, 30, 'test_traceback.py', 'test_with_traceback_exit_throws'), 
                          (Line457+6, 3, 'test_traceback.py', '__exit__')])

Line475=475
def test_with_traceback_ctor_throws():
    class ctx_mgr(object):
        def __init__(self):
            raise Exception('hello')
        def __enter__(*args):
            pass
        def __exit__(*args):
            pass
    
    def h():
        raise Exception('hello!!')
        
    try:
        with ctx_mgr():
            h()
    except:
        assert_traceback([(Line475+14, 30, 'test_traceback.py', 'test_with_traceback_ctor_throws'), 
                          (Line475+4, 3, 'test_traceback.py', '__init__')])


Line496=496
def test_with_mixed_stack():
    """tests a stack which is mixed w/ interpreted and non-interpreted frames
because f() has a loop in it"""
    def a():
        with xxx() as abc:
            f()
    
    def f():
        for z in ():
            pass
            
        1/0
    
    class xxx(object):
        def __enter__(*args): pass
        def __exit__(*args): pass
    
    try:
        a()
    except:
        assert_traceback([(Line496+19, 30, 'test_traceback.py', 'test_with_mixed_stack'), 
                        (Line496+6, 3, 'test_traceback.py', 'a'),
                        (Line496+12, 3, 'test_traceback.py', 'f')])
                          
run_test(__name__)
